{"level":"ERROR","location":"[exception:108] fyers_logger","message":"'ltp'","timestamp":"2025-02-17 19:10:57,612+0530","service":"FyersDataSocket","exception":"Traceback (most recent call last):\n  File \"C:\\Users\\neelam\\AppData\\Local\\Programs\\Python\\Python39\\lib\\site-packages\\fyers_apiv3\\FyersWebsocket\\data_ws.py\", line 1433, in On_message\n    self.OnMessage(message)\n  File \"D:\\aseem\\Fyers\\fyers_subscribe_n1_noRe.py\", line 145, in onmessage\n    ltpDict[message['symbol']] = message['ltp']\nKeyError: 'ltp'","exception_name":"KeyError"}
{"level":"ERROR","location":"[On_message:1443] data_ws","message":"KeyError: The key 'ltp' is missing in the response.","timestamp":"2025-02-17 19:10:57,628+0530","service":"FyersDataSocket"}
{"level":"ERROR","location":"[exception:108] fyers_logger","message":"'ltp'","timestamp":"2025-02-17 19:10:58,063+0530","service":"FyersDataSocket","exception":"Traceback (most recent call last):\n  File \"C:\\Users\\neelam\\AppData\\Local\\Programs\\Python\\Python39\\lib\\site-packages\\fyers_apiv3\\FyersWebsocket\\data_ws.py\", line 1433, in On_message\n    self.OnMessage(message)\n  File \"D:\\aseem\\Fyers\\fyers_subscribe_n1_noRe.py\", line 145, in onmessage\n    ltpDict[message['symbol']] = message['ltp']\nKeyError: 'ltp'","exception_name":"KeyError"}
{"level":"ERROR","location":"[On_message:1443] data_ws","message":"KeyError: The key 'ltp' is missing in the response.","timestamp":"2025-02-17 19:10:58,064+0530","service":"FyersDataSocket"}
{"level":"ERROR","location":"[exception:108] fyers_logger","message":"Invalid header value b'access_token = \"eyJ0eXAiOiJKV1QiLCJhbGciOiJIUzI1NiJ9.eyJpc3MiOiJhcGkuZnllcnMuaW4iLCJpYXQiOjE3Mzk3OTYzNzQsImV4cCI6MTczOTgzODYxNCwibmJmIjoxNzM5Nzk2Mzc0LCJhdWQiOlsieDowIiwieDoxIiwieDoyIiwiZDoxIiwiZDoyIiwieDoxIiwieDowIl0sInN1YiI6ImFjY2Vzc190b2tlbiIsImF0X2hhc2giOiJnQUFBQUFCbnN5LVdPZG5UOFY0ZkV6LUFHUkJwU2pwYW9MZFFDTHhralVjRnBFVWJtbXNBUzdOUlRCRzU4ZE02SW11LWtBTDA5bXdkd0tTUDU0WVRudGxpcHg3RU13M3dxNURKbHF3cl84VzhZNFdmV0lwZXBaTT0iLCJkaXNwbGF5X25hbWUiOiJBU0hJU0ggU0hBUk1BIiwib21zIjoiSzEiLCJoc21fa2V5IjoiM2JhOWQ3M2JkZjk0NDYyZTRjZTczZmRhZjdkYTg3MzM0OTEzZTBiNjlhMWM4Njc1NGYyMzA2ZmMiLCJpc0RkcGlFbmFibGVkIjoiTiIsImlzTXRmRW5hYmxlZCI6Ik4iLCJmeV9pZCI6IlhBMDAzMzAiLCJhcHBUeXBlIjoxMDAsInBvYV9mbGFnIjoiTiJ9.qnRY4kWiYa64bdlHdtM_bEQu2b_qIB1C-agR77xg_ws\"\\n'","timestamp":"2025-02-17 19:10:59,403+0530","service":"FyersDataSocket","exception":"Traceback (most recent call last):\n  File \"C:\\Users\\neelam\\AppData\\Local\\Programs\\Python\\Python39\\lib\\site-packages\\fyers_apiv3\\FyersWebsocket\\data_ws.py\", line 63, in symbol_to_hsmtoken\n    response = requests.post(\n  File \"C:\\Users\\neelam\\AppData\\Local\\Programs\\Python\\Python39\\lib\\site-packages\\requests\\api.py\", line 115, in post\n    return request(\"post\", url, data=data, json=json, **kwargs)\n  File \"C:\\Users\\neelam\\AppData\\Local\\Programs\\Python\\Python39\\lib\\site-packages\\requests\\api.py\", line 59, in request\n    return session.request(method=method, url=url, **kwargs)\n  File \"C:\\Users\\neelam\\AppData\\Local\\Programs\\Python\\Python39\\lib\\site-packages\\requests\\sessions.py\", line 589, in request\n    resp = self.send(prep, **send_kwargs)\n  File \"C:\\Users\\neelam\\AppData\\Local\\Programs\\Python\\Python39\\lib\\site-packages\\requests\\sessions.py\", line 703, in send\n    r = adapter.send(request, **kwargs)\n  File \"C:\\Users\\neelam\\AppData\\Local\\Programs\\Python\\Python39\\lib\\site-packages\\requests\\adapters.py\", line 486, in send\n    resp = conn.urlopen(\n  File \"C:\\Users\\neelam\\AppData\\Local\\Programs\\Python\\Python39\\lib\\site-packages\\urllib3\\connectionpool.py\", line 716, in urlopen\n    httplib_response = self._make_request(\n  File \"C:\\Users\\neelam\\AppData\\Local\\Programs\\Python\\Python39\\lib\\site-packages\\urllib3\\connectionpool.py\", line 416, in _make_request\n    conn.request(method, url, **httplib_request_kw)\n  File \"C:\\Users\\neelam\\AppData\\Local\\Programs\\Python\\Python39\\lib\\site-packages\\urllib3\\connection.py\", line 244, in request\n    super(HTTPConnection, self).request(method, url, body=body, headers=headers)\n  File \"C:\\Users\\neelam\\AppData\\Local\\Programs\\Python\\Python39\\lib\\http\\client.py\", line 1285, in request\n    self._send_request(method, url, body, headers, encode_chunked)\n  File \"C:\\Users\\neelam\\AppData\\Local\\Programs\\Python\\Python39\\lib\\http\\client.py\", line 1326, in _send_request\n    self.putheader(hdr, value)\n  File \"C:\\Users\\neelam\\AppData\\Local\\Programs\\Python\\Python39\\lib\\site-packages\\urllib3\\connection.py\", line 224, in putheader\n    _HTTPConnection.putheader(self, header, *values)\n  File \"C:\\Users\\neelam\\AppData\\Local\\Programs\\Python\\Python39\\lib\\http\\client.py\", line 1263, in putheader\n    raise ValueError('Invalid header value %r' % (values[i],))\nValueError: Invalid header value b'access_token = \"eyJ0eXAiOiJKV1QiLCJhbGciOiJIUzI1NiJ9.eyJpc3MiOiJhcGkuZnllcnMuaW4iLCJpYXQiOjE3Mzk3OTYzNzQsImV4cCI6MTczOTgzODYxNCwibmJmIjoxNzM5Nzk2Mzc0LCJhdWQiOlsieDowIiwieDoxIiwieDoyIiwiZDoxIiwiZDoyIiwieDoxIiwieDowIl0sInN1YiI6ImFjY2Vzc190b2tlbiIsImF0X2hhc2giOiJnQUFBQUFCbnN5LVdPZG5UOFY0ZkV6LUFHUkJwU2pwYW9MZFFDTHhralVjRnBFVWJtbXNBUzdOUlRCRzU4ZE02SW11LWtBTDA5bXdkd0tTUDU0WVRudGxpcHg3RU13M3dxNURKbHF3cl84VzhZNFdmV0lwZXBaTT0iLCJkaXNwbGF5X25hbWUiOiJBU0hJU0ggU0hBUk1BIiwib21zIjoiSzEiLCJoc21fa2V5IjoiM2JhOWQ3M2JkZjk0NDYyZTRjZTczZmRhZjdkYTg3MzM0OTEzZTBiNjlhMWM4Njc1NGYyMzA2ZmMiLCJpc0RkcGlFbmFibGVkIjoiTiIsImlzTXRmRW5hYmxlZCI6Ik4iLCJmeV9pZCI6IlhBMDAzMzAiLCJhcHBUeXBlIjoxMDAsInBvYV9mbGFnIjoiTiJ9.qnRY4kWiYa64bdlHdtM_bEQu2b_qIB1C-agR77xg_ws\"\\n'","exception_name":"ValueError"}
{"level":"ERROR","location":"[exception:108] fyers_logger","message":"'NoneType' object is not subscriptable","timestamp":"2025-02-17 19:10:59,475+0530","service":"FyersDataSocket","exception":"Traceback (most recent call last):\n  File \"C:\\Users\\neelam\\AppData\\Local\\Programs\\Python\\Python39\\lib\\site-packages\\fyers_apiv3\\FyersWebsocket\\data_ws.py\", line 1333, in __symbol_conversion\n    if symbol_value[3] != \"\":\nTypeError: 'NoneType' object is not subscriptable","exception_name":"TypeError"}
{"level":"ERROR","location":"[<lambda>:1663] data_ws","message":"[WinError 10054] An existing connection was forcibly closed by the remote host","timestamp":"2025-02-17 19:41:58,716+0530","service":"FyersDataSocket"}
{"level":"ERROR","location":"[<lambda>:1663] data_ws","message":"[SSL: CERTIFICATE_VERIFY_FAILED] certificate verify failed: self signed certificate (_ssl.c:1129)","timestamp":"2025-02-17 19:42:03,801+0530","service":"FyersDataSocket"}
{"level":"ERROR","location":"[<lambda>:1663] data_ws","message":"[SSL: CERTIFICATE_VERIFY_FAILED] certificate verify failed: self signed certificate (_ssl.c:1129)","timestamp":"2025-02-17 19:42:08,839+0530","service":"FyersDataSocket"}
{"level":"ERROR","location":"[<lambda>:1663] data_ws","message":"[SSL: CERTIFICATE_VERIFY_FAILED] certificate verify failed: self signed certificate (_ssl.c:1129)","timestamp":"2025-02-17 19:42:13,885+0530","service":"FyersDataSocket"}
{"level":"ERROR","location":"[<lambda>:1663] data_ws","message":"[SSL: CERTIFICATE_VERIFY_FAILED] certificate verify failed: self signed certificate (_ssl.c:1129)","timestamp":"2025-02-17 19:42:18,926+0530","service":"FyersDataSocket"}
{"level":"ERROR","location":"[<lambda>:1663] data_ws","message":"[SSL: CERTIFICATE_VERIFY_FAILED] certificate verify failed: self signed certificate (_ssl.c:1129)","timestamp":"2025-02-17 19:42:23,972+0530","service":"FyersDataSocket"}
